Workbook

Sheet Portafolio_Proyectos
A1: Programa estratégico | B1: Sistema productivo | C1: Área temática | D1: Nombre del proyecto | E1: Investigador líder | F1: Rol CI Palmira | G1: Institución ejecutora | H1: Aliados estratégicos | I1: Rol del aliado | J1: Problema abordado | K1: Objetivo del proyecto | L1: Justificación estratégica | M1: Política pública asociada | N1: Metodología principal | O1: Variables evaluadas | P1: Tipo de intervención (I+D+i, Canales OT, Fortalecimiento) | Q1: Resultados principales | R1: Productos generados | S1: Publicaciones | T1: Oferta tecnológica | U1: Tipo de tecnología | V1: TRL inicial | W1: TRL final | X1: Estado tecnológico | Y1: Impacto técnico | Z1: Impacto económico | AA1: Impacto social | AB1: Impacto ambiental | AC1: Departamentos | AD1: Municipios | AE1: Tipo de beneficiarios | AF1: Beneficiarios directos | AG1: Beneficiarios indirectos | AH1: Área potenciales de adopción | AI1: Activos generados | AJ1: Estado propiedad intelectual | AK1: Financiador | AL1: Monto del proyecto | AM1: Año inicio | AN1: Año final | AO1: Estado del proyecto | AP1: Capacidad_emergente | AQ1: Capacidad_consolidada | AR1: Capacidad_distintiva
A2: Bioeconomía: Prácticas de agricultura sostenible | B2: Aguacate Hass | C2: Fisiología vegetal y nutrición | D2: Convenio 1790. Manejo integrado del cultivo | E2: Alexander Rebolledo Roa | F2: Ejecutor | G2: AGROSAVIA | H2: 1. Colciencias 2. Aproare 3. Asfruher | I2: 1. Financiador 2 y 3. Vertice sociedad civil organizada | J2: Desconocimiento de factores hídricos y nutricionales asociados a productividad del cultivo (Abscisión, cuajado, rendimiento y calidad de fruto) | K2: Optimizar la floración y productividad del aguacate Hass mediante manejo hídrico y nutricional. | L2: Los bajos rendimientos del aguacate combinado con la proyección de nuevas zonas de siembra para incrementar la participación en el mercado internacional, requieren del desarrollo de tecnologías que conduzcan a un incremento en la productividad. | M2: CONPES 3582 DEL 25 DE ABRIL DE 2009 "Política Nacional de Ciencia, Tecnología e Innovación" | N2: Nutrición. metodología del índice de balance de nutrientes (ibn) Kenworthy . Riego. cálculo de la ETo por el método de la FAO-Penman Monteith (Allen et al., 2006) y el cálculo de la lámina de riego con base en el balance hídrico. | O2: 1. Abscisión 2. Crecimiento del fruto (MS, diámetro, Peso). 3. Estados fenológicos 4. Variables climáticas 5. Contenido nutrientes del suelo 6. Contenido mineral del fruto | P2: Investigación | Q2: 1. Caracterización de la fenología floral (140 días a antesis), 2. Abscisión global. 99,85 % (276.455 flores) 3. Cuajado. 0,15 % 4. Incremento en rendimiento con manejo de IBN + riego. de 7,5 a 14 t/ha y la producción por planta de 61 a 98 kg. | R2: 1. Protocolo aplicación láminas de riego Antioquia, Tolima, Cauca (Fase 1. Palmira) 2. Protocolo para manejo de la fertilización (Antioquia, Tolima, Cauca) (Fase 1). | S2: Artículo científico. Pattern of flower and fruit abscision and fruit growth of hass avocado under tropical conditions chrome-extension://efaidnbmnnnibpcajpcglclefindmkaj/ https://www.cropj.com/Roa_18_09_2024_547_554.pdf Libros. 1. Criterios para la definición de planes de fertilización en el cultivo de aguacate Hass con un enfoque tecnificado https://doi.org/10.21930/agrosavia.manual.7402384 2. Requerimientos hídricos del cultivo de aguacate (Persea americana) variedad Hass en zonas productoras de Colombia https://doi.org/10.21930/agrosavia.manual.7402322 | U2: Resultado de investigación | V2: 46115 | W2: No definido | X2: Investigación | Y2: 1. Disponibilidad de proocolos estandarizados para aplicación de nutrición y riego. 2. Incremento den rendimiento | Z2: ncremento de la productividad del cultivo (de 7,5 a 14 t/ha), mejorando la rentabilidad del sistema productivo de aguacate Hass. | AA2: Fortalecimiento de las capacidades de manejo productivo de los agricultores mediante prácticas de riego y nutrición más eficientes. | AB2: Uso más eficiente del agua y de los nutrientes mediante manejo hídrico y nutricional basado en criterios técnicos. | AC2: Antioquia, Tolima, Cauca | AD2: Rionegro, Herveo, Morales | AE2: Asociación de productores | AF2: Asociación de Productores de Frutas y Hortalizas de Herveo (ASFRUHER) Asociación de Productores de Aguacate de El Retiro (APROARE) | AG2: Productores de aguacate Hass de Herveo (Tolima) y El Retiro (Antioquia), técnicos y otros productores de las zonas productoras de aguacate en Colombia. | AH2: Zonas productoras de aguacate Hass a nivel nacional | AI2: NA | AJ2: NA | AK2: Colciencias | AL2: 3000000000 | AM2: 2013 | AN2: 2016 | AO2: Finalizado | AP2: Indicadores de sostenibilidad ambiental
A3: Bioeconomía: Biodiversidad | B3: Agraz | C3: Fisiología vegetal y nutrición | D3: Aprovechamiento sostenible de agraz en el Cauca | AK3: Entes Nacionales y Territoriales
A4: Bioeconomía: Biodiversidad | B4: Agraz | C4: Material de siembra y mejoramiento genético | D4: Aprovechamiento sostenible de agraz en el Cauca | AK4: Entes Nacionales y Territoriales
A5: Bioeconomía: Biodiversidad | B5: Agraz | C5: Material de siembra y mejoramiento genético | D5: Aprovechamiento sostenible de agraz en el Cauca | AK5: Entes Nacionales y Territoriales
A6: ACI:Productividad agrícola agroambientalmente eficiente e integralmente sostenible | B6: Aguacate Hass | C6: Fisiología vegetal y nutrición | D6: Convenio 1929. Desarrollo y validación de tecnologías para incrementar la productividad del cultivo | E6: Alexander Rebolledo Roa | F6: Ejecutor | G6: AGROSAVIA | H6: 1. Gobernación del Cauca, 2. Universidad del Cauca | I6: 1. Supervisor. 2. Cojejecutor Vertice Institución de educación superior | J6: Baja disponibilidad de opciones tecnológicas para el manejo de riego y nutrición | K6: Validar tecnologías de nutrición y riego para incrementar productividad del aguacate Hass en el Cauca | L6: Mejora la eficiencia hídrica y nutricional en aguacate Hass, reduciendo alternancia de cosechas y aumentando rendimiento en zonas productoras del Cauca | M6: CONPES 3582 — Política Nacional de Ciencia, Tecnología e Innovación; Plan Nacional de Desarrollo | N6: IBN de Kenworthy (1973); ETo FAO-Penman-Monteith (Allen et al., 2006); lámina de riego por balance hídrico; escala fenológica BBCH (Alcaraz et al., 2013) | O6: Diámetro de fruto, peso fresco, peso seco, materia seca, abscisión, cuajado, estados fenológicos BBCH, IBN foliar, ETo, lámina de riego | P6: Desarrollo | Q6: Fertilización basada en IBN incrementó diámetro de fruto (T2: 61,43 mm vs T1: 54,77 mm). Abscisión 98–99,9%. Cuajado 0,15–0,87%. Riego 0,75 ETo mejoró peso seco del mesocarpo | R6: Protocolo de fertilización basada en IBN para aguacate Hass Cauca, protocolo de riego por balance hídrico, modelo fenológico BBCH, aplicativo web de recomendación nutricional e hídrica | S6: 1. Criterios para la definición de planes de manejo de la fertilización y para la aplicación de riego en cultivos de aguacate Hass con un enfoque tecnificado. https://editorial.agrosavia.co/index.php/publicaciones/catalog/book/355. 2. Prácticas de manejo sostenible para fertilización y riego de aguacate Hass en el departamento del Cauca. https://editorial.agrosavia.co/index.php/publicaciones/catalog/book/357 3. Nutrient balance in Hass avocado trees as a tool to optimize crop fertilization management. https://www.mdpi.com/2073-4395/13/8/1956 4. Rodríguez P., Villamizar J., Rebolledo A. (2025). Impact of Fruit Development Age on Postharvest Quality of Hass Avocado. Int J Fruit Sci, 25, 18–35. DOI: 10.1080/15538362.2025.2480570 Rebolledo-Roa A., Burbano-Díaz R.A., Medina-Cano C.I. (2024). | T6: Sistema Experto TecnoHass | U6: Aplicativo Web | V6: 5 | W6: 7 | X6: Finalizado | Y6: Incremento de 12% en diámetro de fruto con fertilización IBN; reducción de abscisión ~1,4% con fertilización foliar B+N en estado fenológico coliflor EF515 | Z6: Mayor proporción de frutos en calibres comerciales de alto valor (178–325 g/fruto) con fertilización IBN; rendimiento de hasta 17 t/ha en finca con riego vs promedios menores sin manejo | AA6: 1.440 productores de aguacate Hass de Morales, El Tambo y municipios del Cauca beneficiados con tecnologías de nutrición y riego de alta precisión y bajo costo de implementación | AB6: Uso eficiente del agua con riego 0,75 ETo; reducción de fertilizantes excesivos mediante IBN, disminuyendo riesgo de lixiviación de nutrientes y contaminación de fuentes hídricas | AC6: Cauca | AD6: Morales, Cajibío, Piendamó, Caldono, Tambo, Timbío, Popayán, Sotará, Caloto, Corinto, Toribío. | AE6: Asociación de productores | AF6: 1440 | AG6: Productores de aguacate Hass de zonas productoras del Cauca y regiones andinas colombianas con condiciones agroecológicas similares | AH6: Departamento del Cauca y zonas productoras de aguacate Hass en regiones andinas colombianas | AI6: Aplicativo Web | AK6: Sistema General de Regalías-Cauca | AM6: 2018 | AN6: 2023 | AO6: En ejecución | AP6: Indicadores de sostenibilidad ambiental | AQ6: Fertilización por sitio específico
A7: ACI:Productividad agrícola agroambientalmente eficiente e integralmente sostenible | B7: Aguacate Hass | C7: Fisiología vegetal y nutrición | D7: Portafolio. Fortalecimiento cadena de valor de aguacate. Convocatoria 42. SGR-Región Pacífico | E7: Alexander Rebolledo Roa | F7: Líder | G7: AGROSAVIA | H7: SENA CEAI, Universidad Cooperativa de Colombia, CREATIC, BIOINNOVA, Cámara de Comercio de Palmira, CITRIVIVEROS, Alcaldías de Popayán, Piendamó, El Tambo, Sotará, Palmira, Caicedonia, Versalles, San José del Palmar, asociaciones de productores locales | I7: SENA CEAI: coejecución en actividades de apropiación social del conocimiento y fortalecimiento TIC. Universidad Cooperativa de Colombia: coejecución en cursos de formación sobre plataforma TecnoHass. CREATIC: desarrollo y mejora de plataformas digitales. BIOINNOVA: apropiación social del conocimiento. Cámara de Comercio de Palmira: vinculación tecnológica y fortalecimiento de modelos de negocio. | J7: Deficiente orientación técnica en fertilización y riego en aguacate Hass y Lorena en Cauca y Valle del Cauca | K7: Validar tecnologías de fertilización y riego para aguacate Hass y Lorena en Cauca y Valle del Cauca | L7: Escala tecnologías IBN y balance hídrico de Hass hacia Lorena, ampliando cobertura a Valle del Cauca y cerrando brecha tecnológica en ambos sistemas productivos | M7: PND 2022-2026 'Colombia Potencia Mundial de la Vida', Convergencia Regional; CONPES 4069 de 2021 CTI; Planes de Desarrollo Departamentales Cauca y Valle del Cauca | N7: IBN de Kenworthy (1973); ETo FAO-Penman Monteith (Allen et al., 2006); escala BBCH (Salazar-García et al., 1998); monitoreo Agro 4.0 de variables climáticas | O7: Diámetro y peso del fruto, materia seca, calibre Codex, rendimiento kg/árbol, abscisión, cuajado, IBN foliar, ETo y lámina de riego, estados fenológicos BBCH | P7: Innovación | Q7: Fertilización IBN incrementó producción de 7 a 14 t/ha; lámina 75% ETo fue óptima; fertilización foliar N+B aumentó producción en 14 t/ha; rendimiento de hasta 20 kg/árbol con IBN | R7: Planes de manejo de nutrición y riego (Hass y Lorena, Cauca y Valle del Cauca), módulo fertilización y riego TecnoHass (TRL 8), manuales técnicos, artículos científicos indexados | S7: Rebolledo A. y Dorado J. (2017). Manejo de la fertilización y del riego en cultivos de aguacate Hass en Cauca. AGROSAVIA. Rebolledo A. y Burbano R.A. (2023). Nutrición basada en IBN para aguacate Hass en condiciones tropicales colombianas. AGROSAVIA. Rodríguez P. et al. (2023). Factores territoriales y calidad del fruto en sistemas de aguacate en la región pacífico. AGROSAVIA. | T7: Protocolos de fertilización y riego para aguacate Hass y Lorena integrados en plataforma TecnoHass (Cauca y Valle del Cauca) | U7: Resultado de investigación / Herramienta tecnológica digital (aplicativo web) | V7: 4 | W7: 8 | X7: En ejecución | Y7: Incremento de 7 a 14 t/ha con IBN + riego 75% ETo; mayor proporción calibre 22 (165–196 g); menor descarte | Z7: Reducción de descarte en planta exportadora del 6%; incremento de 20 kg/árbol con IBN (segundo año de cosecha); potencial de reducción de pérdidas poscosecha del 60% | AA7: 889 productores (Hass y Lorena) en Cauca y Valle del Cauca con acceso a tecnologías de nutrición y riego de precisión | AB7: Reducción del uso indiscriminado de fertilizantes de síntesis química; uso eficiente del agua (riego por ETo vs gravedad); disminución de escorrentía y riesgo de lixiviación de nutrientes | AC7: Chocó, Cauca, Valle del Cauca | AD7: San José del Palmar, El Tambo, Piendamó, Sotará, Popayán, Caicedonia, Versalles, Palmira | AE7: Asociación de productores | AF7: 889 | AG7: Productores de aguacate Hass y Lorena en subregiones del Cauca y Valle del Cauca no incluidos directamente; asistentes técnicos y extensionistas agropecuarios de la región | AH7: Zonas productoras de aguacate Hass (exportación) y Lorena (consumo interno) en Cauca y Valle del Cauca; extensible a región pacífico | AI7: Aplicativo web TecnoHass — módulo fertilización y riego (TRL 8); protocolos de manejo nutricional y de riego para aguacate Hass y Lorena; bases de datos de extracción de nutrientes y curvas de crecimiento de fruto | AK7: Entes Nacionales y Territoriales | AL7: 24876204138 | AM7: 2024 | AN7: 2027 | AO7: En ejecución | AP7: Nutrición y riego para aguacate de consumo interno (Lorena) | AQ7: Fertilización por sitio específico (IBN) y riego por balance hídrico
A8: Bioeconomía: Prácticas de agricultura sostenible | B8: Aguacate Hass | C8: Fisiología vegetal y nutrición | D8: Convenio 2207. Desarrollo de modelo fenológico aguacate Hass Pijao – Quindío (Fase 1) | E8: Alexander Rebolledo Roa | F8: Líder | G8: AGROSAVIA | H8: Global Green SAS | I8: Financiador y co-ejecutor técnico de apoyo logístico en campo; propietario de los activos instalados (estaciones climáticas) | J8: Ausencia de modelo fenológico predictivo para aguacate Hass en gradiente altitudinal andino del Quindío que dificulta el manejo oportuno del cultivo | K8: Desarrollar un modelo fenológico predictivo basado en GDD para aguacate Hass en gradiente altitudinal de Pijao, Quindío | L8: Permite anticipar eventos críticos (floración, cosecha) con base en temperatura acumulada, optimizando manejo agronómico y reduciendo incertidumbre productiva | M8: Plan Nacional de Desarrollo — Bioeconomía; CONPES 3582 — Política Nacional CTI; Pacto por Colombia — Pacto por la productividad agropecuaria | N8: Escala fenológica BBCH (Alcaraz et al., 2013); grados-día de crecimiento GDD (base 10°C, Aubert 1972); análisis factorial confirmatorio CFA; estadística circular; estaciones GeoCampo/NASA | O8: Estados fenológicos BBCH (EF010–EF719), GDD acumulados, temperatura máx/mín/media, humedad relativa, velocidad del viento, diámetro ecuatorial de fruto, peso fresco, peso seco, materia seca | P8: Investigación | Q8: Gradiente térmico-hídrico determina sincronía fenológica. Altitud ~2200 m es óptima (antesis ρ=0,82). GDD predice progresión fenológica. L3 (~2056 m): 20,58 kg/árbol cosecha 2, materia seca 22,8 % | R8: Documento técnico con modelo fenológico GDD, caracterización climática altitudinal y clasificación Codex; 1 artículo científico sometido a revista indexada; 2 estaciones climáticas automatizadas instaladas | S8: Rebolledo, A., Burbano, R., Villamizar, J., & Corrales, D. (2025). Climatic Drivers of Flowering Synchrony in ‘Hass’ Avocado Under Tropical Andean Conditions. Plants, 14(24), 3822. | T8: Modelo fenológico predictivo basado en GDD para aguacate Hass en gradiente altitudinal andino tropical del Quindío | U8: Resultado de investigación | V8: 2 | W8: 5 | X8: Finalizado | Y8: GDD predice progresión fenológica con alta precisión (CFI=0,976); sincronía óptima en ~2200 m (ρ=0,82); L3 produce frutos 62–64 mm vs L5 55–59 mm | Z8: L3 produce materia seca 22,8 % y aceite 58,5 % base seca (cosecha tardía); rendimiento 20,58 kg/árbol cosecha 2; segmentación de mercado por altitud y momento de cosecha optimiza valor comercial | AA8: 115 beneficiarios directos (productores de aguacate de Pijao, Quindío) con acceso a modelo fenológico que mejora planificación de cosecha y reducción de pérdidas por asincronía floral | AB8: Manejo basado en señales térmicas reales reduce aplicaciones innecesarias de insumos; monitoreo microclimático continuo aporta base para adaptación al cambio climático en sistemas andinos tropicales | AC8: Quindío | AD8: Pijao | AE8: Otro | AF8: 115 | AG8: Productores de aguacate Hass en zonas andinas colombianas con gradiente altitudinal 1600–2500 m.s.n.m. | AH8: Zonas productoras de aguacate Hass en gradiente altitudinal andino 1600–2500 m.s.n.m. en Colombia | AK8: Sector privado | AL8: 496881755 | AM8: 2024 | AN8: 2025 | AO8: Finalizado | AP8: Modelación fenológica con acumulación térmica (GDD) en sistemas frutícolas altoandinos | AQ8: Fertilización por sitio específico
A9: Bioeconomía: Prácticas de agricultura sostenible | B9: Aguacate Hass | C9: Manejo sanitario y fitosanitario | D9: Actividad 6. Generar practicas de manejo fitosanitario de plags de importancia cuarentenaria validadas en regiones productoras del departamento. | AK9: Entes Nacionales y Territoriales
A10: ACI: Adaptación y resiliencia de los sistemas productivos agropecuarios frente a condiciones de clima cambiante | B10: Aguacate Hass | C10: Manejo ambiental y sostenibilidad | D10: convenio 1929. Actividad 1. Valoración de la oferta biofísica y caracterización socioeconómica de sistemas de producción de aguacate para la identificación de nichos productivos y tecnología requerida en el desarrollo de cultivos de aguacate Hass en el Departamento del Cauca. Lider: Diana Lucia Correa Moreno | AK10: Entes Nacionales y Territoriales
A11: Inclusión social en el desarrollo tecnológico: Apropiación social del conocimiento desde la ciencia ciudadana y la ciencia comunitaria | B11: Aguacate Hass | C11: Manejo ambiental y sostenibilidad | D11: convenio 1929. Actividad 6. Divulgación de la oferta tecnológica disponible del sistema productivo de aguacate y las tecnologías validadas . Lider: Diana Lucia Correa Moreno | AK11: Entes Nacionales y Territoriales
A12: Bioeconomía: Biodiversidad | B12: Aguacate Hass | C12: Manejo sanitario y fitosanitario | D12: Aumento de la productividad del aguacate mediante el uso de polinizadores en tres zonas productoras de Colombia. | AK12: Entes Nacionales y Territoriales
A13: ACI: Adaptación y resiliencia de los sistemas productivos agropecuarios frente a condiciones de clima cambiante | B13: Aguacate Hass | C13: Manejo ambiental y sostenibilidad | D13: Reducción del riesgo y adaptación al cambio climático_Modelos de adaptación agroclimática (MAPA). Aguacate Hass (Persea americana Mill.) var. Hass. Facilitadora Regional MAPA: Diana Lucia Correa Moreno | AK13: Entes Nacionales y Territoriales
A14: Otro | B14: Aguacate Hass | C14: Manejo sanitario y fitosanitario | D14: Identificación de ácaros e insectos escamas y sus enemigos naturales promisorios para una producción competitiva de aguacate en Colombia. | AK14: Entes Nacionales y Territoriales
A15: Bioeconomía: Biodiversidad | B15: Aguacate Hass | C15: Material de siembra y mejoramiento genético | D15: Bases tecnológicas para la producción de material de siembra de aguacate de alta calidad Fase 1 | AK15: Entes Nacionales y Territoriales
A16: Bioeconomía: Biodiversidad | B16: Aguacate Hass | C16: Material de siembra y mejoramiento genético | D16: Bases tecnológicas para la producción de material de siembra de aguacate de alta calidad Fase 2 | AK16: Entes Nacionales y Territoriales
A17: Bioeconomía: Economía circular | B17: Aguacate Hass | C17: Material de siembra y mejoramiento genético | D17: Bases tecnológicas para la producción de material de siembra de aguacate de alta calidad Fase 3 | AK17: Entes Nacionales y Territoriales
A18: ACI:Productividad agrícola agroambientalmente eficiente e integralmente sostenible | B18: Aguacate Hass | C18: Manejo ambiental y sostenibilidad | D18: Validación metodológica para caracterizar las condiciones biofísicas, socioeconómicas y productivas a escala 1:25.000, para el cultivo de aguacate en la región productora del Tolima, como soporte para el desarrollo de tecnologías de manejo agronómico del cultivo. Lider: Diana Lucia Correa Moreno | AC18: Tolima | AK18: Entes Nacionales y Territoriales
A19: ACI: Adaptación y resiliencia de los sistemas productivos agropecuarios frente a condiciones de clima cambiante | B19: Aguacate Hass | C19: Manejo ambiental y sostenibilidad | D19: Condiciones biofísicas y socioeconómicas del sistema productivo de aguacate - variedad Lorena caracterizadas en la región productora del Tolima, como soporte para el desarrollo de tecnologías de manejo agronómico específicas. Lider: Diana Lucia Correa Moreno | AC19: Tolima | AK19: Entes Nacionales y Territoriales
A20: ACI: Adaptación y resiliencia de los sistemas productivos agropecuarios frente a condiciones de clima cambiante | B20: Aguacate Hass | C20: Manejo ambiental y sostenibilidad | D20: Caracterización de áreas potenciales con enfoque territorial y de adaptación para el desarrollo y producción de cultivos de aguacate con atributos de valor. Lider: Diana Lucia Correa Moreno | AC20: Tolima | AK20: Entes Nacionales y Territoriales
A21: Bioeconomía: Biodiversidad | B21: Ají | C21: Material de siembra y mejoramiento genético | D21: Selección de materiales de Capsicum spp. con atributos diferenciales y ventajas competitivas agronómicas y agroindustriales | AK21: Entes Nacionales y Territoriales
A22: Bioeconomía: Biodiversidad | B22: Bancos de Germoplasma | C22: Material de siembra y mejoramiento genético | D22: 2025 BGA Conservación en Campo BG Vegetal ID 1003076 | AK22: Entes Nacionales y Territoriales
A23: Bioeconomía: Biodiversidad | B23: Cacao | C23: Material de siembra y mejoramiento genético | D23: Identificación de atributos agronómicos en cacao cuya expresión es afectada por el patrón con miras a establecer un programa de mejoramiento genético de patrones que contribuya a realzar el comportamiento de clones de interés | AK23: Entes Internacionales
A24: Bioeconomía: Biodiversidad | B24: Cacao | C24: Material de siembra y mejoramiento genético | D24: Selección de patrones de cacao mediante la identificación de atributos agronómicos cuya expresión es afectada por el patrón, con miras a establecer un programa de mejoramiento genético de patrones que contribuya a realzar el comportamiento de clones de interés. | AK24: Entes Nacionales y Territoriales
A25: Bioeconomía: Biodiversidad | B25: Cacao | C25: Material de siembra y mejoramiento genético | D25: Evaluación de la acumulación de cadmio de genotipos de cacao, bajo diferentes condiciones edafoclimáticas, como estrategia de mitigación del impacto de contenidos de cadmio biodisponible en suelo | AK25: Entes Internacionales
A26: Bioeconomía: Biodiversidad | B26: Cacao | C26: Material de siembra y mejoramiento genético | D26: Fase II Cacao para la paz | AK26: Entes Internacionales
A27: Bioeconomía: Prácticas de agricultura sostenible | B27: Cacao | C27: Manejo de sistemas productivos | D27: Implementación de recomendaciones tecnológicas orientadas al fortalecimiento de capacidades y desarrollo sostenible del sistema productivo de cacao en el suroccidente colombiano a partir de estrategias participativas | AK27: Entes Internacionales
A28: Bioeconomía: Biodiversidad | B28: Cacao | C28: Material de siembra y mejoramiento genético | D28: Merging eco-physiology and ML to select drought tolerant cacao genotypes | AK28: Entes Internacionales
A29: Bioeconomía: Prácticas de agricultura sostenible | B29: Cacao | C29: Manejo de sistemas productivos | D29: Proyecto 88352 - Aplicación y validación de tecnologías para potencializar la competitividad del sistema productivo de cacao en 8 municipios priorizados del departamento del Cauca | AK29: Entes Nacionales y Territoriales
A30: Bioeconomía: Economía circular | B30: Cacao | C30: Manejo cosecha, poscosecha y transformación | D30: 1002666: Viabilidad centros de fermentación en las regiones cacaoteras de Caldas, Huila y Tolima. | E30: Jader Rodríguez Cortina | F30: Líder | G30: AGROSAVIA | H30: Asociaciones de cacaocultores de Caldas, Huila y Tolima: APROCALG, ASOCAGIGANTE, ASOCAPOTRERILLOS, ASOCARECREO, ASOPECA, ASOPROCAR, ASOCACAO, ASOCATES, APROCAPAL, COCOAGRO, ASOPROBEL, ASOVICA, ASOCAMELIAS, AGROCAMUS, ASPRAFAL, ASOCANORA, ASOCANORCA, ASOSEMILLAS DEL CAMPO, ACA SANDIEGO, AMUCCOL, ASOCAT, ASOESTRELLA, ASOPEP, ASOPROLOMAT, ATACONDOR, RENACER LAS BLANCAS, ASAGROLT, ASOACAS, ASOPEROTOL, AGROEMPORTEGA, AMOCAL, APROCAMAITO, APROCASURT, ASOPROSINEV, ASOCATOL, ASOPARAISO ALTAMIRA, ASOPROMECOL, ECOAPROACIM | I30: Beneficiarios | J30: Baja disponibilidad de herramientas para establecer la viabilidad para establecer centros comunitarios de valorización poscosecha en Caldas, Huila y Tolima | K30: Desarrollar de una herramienta en excel para establecer la viabilidad para establecer centros comunitarios de valorización poscosecha en Caldas, Huila y Tolima | L30: Aumentar las capacidades de planificación en transporte, procesamiento, análisis de utilidades y escenarios de establecimientos de centros comunitarios de valorización poscosecha en Caldas, Huila y Tolima | M30: Plan Nacional de Desarrollo, Planes departamentales de Desarrollo, PECTIA y CONPES | N30: Modelación matemática para transporte, procesamiento poscosecha y análisis de utilidades (a corto y largo plazo) y escenarios de análisis. Desarrrolo de herramienta en Microsoft Excel utilizando Visual Basic for Applications (VBA), Análisis agroclimático, georreferenciación, modelación espacial | O30: Temperatura máxima, temperatura mínima, temperatura media, precipitación, radiación solar, velocidad del viento, presión de vapor, productividad, rendimiento en grano, calidad organoléptica. | P30: I+D+i | Q30: Una (1) zonificación agroclimática, Una (1) herramienta de excel para la planificación en transporte, procesamiento, análisis de utilidades y escenarios de establecimientos de centros comunitarios de valorización poscosecha en Caldas, Huila y Tolima | R30: Una (1) herramienta de excel para la planificación en transporte, procesamiento, análisis de utilidades y escenarios de establecimientos de centros comunitarios de valorización poscosecha en Caldas, Huila y Tolima, mapas agroclimáticos, base de datos georreferenciada, estudio de viabilidad, modelo logístico | T30: Modelo de centros regionales de fermentación para cacao con enfoque agroclimático y logístico | U30: Software | V30: 2 | W30: 5 | X30: 5 | Y30: Mejora en la toma de decisiones para optimizar la fermentación, logística y calidad diferenciada del cacao regional. | Z30: Potencial incremento de ingresos mediante valorización del cacao y aprovechamiento comercial de subproductos poscosecha. | AA30: Beneficio a asociaciones cacaoteras de Caldas, Huila y Tolima mediante fortalecimiento organizacional y acceso a modelos asociativos de valor agregado. | AB30: Promueve aprovechamiento de subproductos del cacao y reducción de pérdidas poscosecha mediante modelos sostenibles de transformación regional. | AC30: Caldas, Huila y Tolima | AD30: Gigante, Rivera, Tesalia, Ospina Pérez, Belalcazar, Mariquita, Norcasia, Santiago Pérez, Ortega, Chaparral | AE30: Asociaciones de cacaocultores y extensionistas | AF30: 600 productores y/o asistentes técnicos | AG30: 2.500 beneficiarios: productores, comercializadores, transformadores y actores regionales de la cadena de valor | AH30: Zonas cacaoteras en Colombia | AI30: Una (1) herramienta de excel para la planificación en transporte, procesamiento, análisis de utilidades y escenarios de establecimientos de centros comunitarios de valorización poscosecha en Caldas, Huila y Tolima | AK30: Entes Internacionales | AL30: 438479075 | AM30: 2023 | AN30: 2025 | AO30: Finalizado | AR30: Desarrollo de oferta tecnológica transferible Capacidad de convertir ciencia en productos de valor
A31: Bioeconomía: Economía circular | B31: Cacao | C31: Manejo cosecha, poscosecha y transformación | D31: ID: 1002667. Establecimiento de protocolos apropiados de fermentación basados en perfiles sensoriales del cacao en Caldas, Huila y Tolima. | E31: Jader Rodríguez Cortina | F31: Líder | G31: AGROSAVIA | H31: Asociaciones de cacaocultores de Caldas, Huila y Tolima: APROCALG, ASOCAGIGANTE, ASOCAPOTRERILLOS, ASOCARECREO, ASOPECA, ASOPROCAR, ASOCACAO, ASOCATES, APROCAPAL, COCOAGRO, ASOPROBEL, ASOVICA, ASOCAMELIAS, AGROCAMUS, ASPRAFAL, ASOCANORA, ASOCANORCA, ASOSEMILLAS DEL CAMPO, ACA SANDIEGO, AMUCCOL, ASOCAT, ASOESTRELLA, ASOPEP, ASOPROLOMAT, ATACONDOR, RENACER LAS BLANCAS, ASAGROLT, ASOACAS, ASOPEROTOL, AGROEMPORTEGA, AMOCAL, APROCAMAITO, APROCASURT, ASOPROSINEV, ASOCATOL, ASOPARAISO ALTAMIRA, ASOPROMECOL, ECOAPROACIM | I31: Beneficiarios | J31: Baja disponibilidad de protocolos de fermentación enfocados en obtención de cacao de calidad superior en Caldas, Huila y Tolima | K31: Desarrollar protocolos de fermentación basados en perfiles sensoriales del cacao de Caldas, Huila y Tolima. | L31: Aumentar la visibilización y valorización comercial del potencial de calidad del cacao regional en Caldas, Huila y Tolima a través de la aplicación de adecuadas prácticas poscosecha | M31: Plan Nacional de Desarrollo, Planes departamentales de Desarrollo, PECTIA y CONPES | N31: Metodología de fermentación espontánea con monitoreo de temperatura y pH, y análisis descriptivo de calidad sensorial en cacao según estándares internacionales COEX y CIRAD, Tipificación agroecológica | O31: Zonas agroecológicas, tiempo de fermentación, temperatura de tostado | P31: I+D+i | Q31: 200 Perfiles sensoriales de calidad de 10 zonas agroecológicas en Caldas, Huila y Tolima y recomendaciones de buenas prácticas poscosecha para potenciar la calidad | R31: 200 Perfiles sensoriales de calidad de 10 zonas agroecológicas en Caldas, Huila y Tolima, recomendaciones de buenas prácticas poscosecha para potenciar la calidad, protocolos de fermentación, base de datos espacial, mapas agroecológicos | T31: Protocolos regionales de fermentación para cacao basados en perfiles sensoriales y zonificación agroecológica. | U31: Protocolos | V31: 3 | W31: 6 | X31: 6 | Y31: Estandarización de fermentación y diferenciación sensorial del cacao en 10 zonas agroecológicas en Caldas, Huila y Tolima. | Z31: Potencial incremento de ingresos mediante comercialización de cacao diferenciado con perfiles sensoriales demandados por mercados internacionales. | AA31: Beneficio a productores cacaoteros de Caldas, Huila y Tolima mediante fortalecimiento de capacidades para producir cacao diferenciado de calidad superior y de mayor valor comercial. | AB31: Promueve manejo poscosecha adaptado a condiciones agroecológicas regionales, favoreciendo uso eficiente de recursos y valorización territorial del cacao. | AC31: Caldas, Huila y Tolima | AD31: Gigante, Rivera, Tesalia, Ospina Pérez, Belalcazar, Mariquita, Norcasia, Santiago Pérez, Ortega, Chaparral | AE31: Asociaciones de cacaocultores y extensionistas | AF31: 600 productores y/o asistentes técnicos | AG31: 2.500 beneficiarios: productores, comercializadores, transformadores y actores regionales de la cadena de valor | AH31: Zonas cacaoteras en Colombia | AI31: Equipos para transformación bean to bar de la minichocolatería de la planta de poscosecha | AK31: Entes Internacionales | AL31: 992001757 | AM31: 2023 | AN31: 2025 | AO31: Finalizado | AQ31: Calidad sensorial de cacao Protocolos de fermentación y secado
A32: Bioeconomía: Economía circular | B32: Cacao | C32: Manejo cosecha, poscosecha y transformación | D32: ID: 1002841. Implementación de un modelo para el aprovechamiento integral de las mazorcas de cacao para la generación de productos de valor agregado por medio de alternativas biotecnológicas | E32: Jader Rodríguez Cortina | F32: Líder | G32: AGROSAVIA | H32: Asociación de productores campesinos de Cisneros | I32: Beneficiarios | J32: Alta generación y subutilización de residuos de mazorca de cacao, causando impactos ambientales y baja valorización en sistemas productivos cacaoteros rurales. | K32: Implementar alternativas biotecnológicas para valorizar residuos de mazorca de cacao mediante compostaje, digestión anaerobia y pirólisis | L32: Fortalece la economía circular y la sostenibilidad rural mediante valorización de residuos, generación de bioinsumos y reducción de impactos ambientales en territorios PDET. | M32: Plan Nacional de Desarrollo, Plan departamental de Desarrollo el Valle del Cauca, y PECTIA | N32: Pirólisis para producción de biochar, compostaje y digestión anaerobia; caracterización fisicoquímica, diseño experimental de mezclas, análisis multicriterio TOPSIS y evaluación agronómica (Parra et al 2022) | O32: Temperatura, sólidos totales, ácidos grasos volátiles, metales pesados, nutrientes (NPK), acidez, pH, humedad, conductividad eléctrica, carbono orgánico total, sólidos volátiles, nitrógeno total, fósforo total, producción de metano, índice de germinación, biomasa aérea. | P32: I+D+i | Q32: Obtención de biochar, compost y digestato valorizados; implementación de prototipos piloto y validación agronómica de bioinsumos derivados de residuos de cacao. | R32: 1 prototipo de reactor anaerobio, 1 protocolo de operación, 1 artículo científico, 1 herramienta multicriterio para la selección de biomasa | S32: Parra-Orobio, B., Rodríguez-Cortina, J., Serna-Jiménez, J., Escobar-Parra, S., Santander-Muñoz, M., Martínez-Ruiz, Y., Álvarez-Trujillo, J.D., Soto-Paz, J. Hybrid decision-making tool for selecting co-substrates for the energy and agricultural valorization of cacao pod husk residues within a circular economy model. | U32: Equipos y protocolos | V32: 3 | W32: 6 | X32: 6 | Y32: Implementación piloto de tecnologías biotecnológicas para valorización de residuos, generando bioinsumos y bioproductos con potencial de aplicación agrícola y energética. | Z32: Generación de productos de valor agregado y reducción potencial de costos asociados al manejo de residuos y fertilización convencional | AA32: Beneficio a asociaciones cacaoteras rurales PDET y ZOMAC mediante transferencia tecnológica, fortalecimiento comunitario y participación de mujeres, jóvenes y grupos étnicos | AB32: Reducción de residuos agrícolas y mitigación de impactos sobre suelo mediante aprovechamiento circular, producción de biofertilizantes y disminución potencial de emisiones GEI | AC32: Valle del Cauca | AD32: Cisneros | AE32: Asociaciones de cacaocultores y extensionistas, comunidad académica y de investigación | AF32: 350 productores y/o asistentes técnicos | AG32: 1.800 beneficiarios | AH32: Zonas cacaoteras en Colombia | AI32: Sistema de biodigestión Anaerobia escala piloto, zona de compostaje a escala laboratorio | AK32: Entes Nacionales y Territoriales | AL32: 290000000 | AM32: 2024 | AN32: 2026 | AO32: En ejecución | AQ32: Valorización de subproductos Diseño de equipos de poscosecha Escalamiento de tecnologías en cacao | AR32: Enfoque de bioeconomía en cacao Desarrollo de oferta tecnológica transferible Capacidad de convertir ciencia en productos de valor
A33: Otro | B33: Cacao | C33: Manejo cosecha, poscosecha y transformación | D33: Idea. 0007950. Estrategia poscosecha para la inocuidad y comercio del cacao colombiano | E33: Margareth Santander | F33: Líder | G33: AGROSAVIA | H33: IICA, Asociaciones de cacaocultores de Tumaco | I33: Beneficiarios | AK33: Entes Internacionales
A34: Bioeconomía: Economía circular | B34: Cacao | C34: Manejo cosecha, poscosecha y transformación | D34: Idea. 0007978. Bioeconomía en cacao | E34: Margareth Santander | F34: Líder | G34: AGROSAVIA | H34: CIRAD, Asociaciones de cacaocultores de Caldas y Nariño | I34: Beneficiarios | AK34: Entes Internacionales
A35: Bioeconomía: Prácticas de agricultura sostenible | B35: Cacao | C35: Manejo de sistemas productivos | D35: Proyecto 95883. IMPLEMENTACIÓN DE INNOVACIONES TECNOLÓGICAS BAJO UN MODELO DE ECONOMÍA CIRCULAR, SOCIAL Y SOLIDARIA COMO APORTE A LA SEGURIDAD ALIMENTARIA Y A LA TRANSICIÓN SOSTENIBLE HACIA UN DESARROLLO AGRÍCOLA Y AGROINDUSTRIAL EN 4 MUNICIPIOS DEL DEPARTAMENTO DEL VALLE DEL CAUCA | AK35: Entes Nacionales y Territoriales
A36: Bioeconomía: Economía circular | B36: Cacao | C36: Manejo cosecha, poscosecha y transformación | D36: ID 001451: SGR Arauca poscosecha | E36: Jader Rodríguez Cortina | F36: Líder | G36: AGROSAVIA | H36: Asociaciones de cacaocultores de Arauca: COOMPROCAR, Coopcacao y CABEFAMI, Fedecacao, CIRAD | I36: Beneficiarios, aliados científicos para análisis de calidad, y aliados para trabajo en territorio | J36: Baja innovación tecnológica en productividad, inocuidad, calidad poscosecha y articulación empresarial de la cadena cacaotera en Arauca | K36: Implementar estrategias agroforestales y tecnologías agronómicas y poscosecha para mejorar productividad, inocuidad y calidad del cacao en Arauca. | L36: Fortalece la competitividad del cacao especial mediante innovación tecnológica, sostenibilidad productiva y acceso a mercados diferenciados con mayor valor agregado | M36: Plan Nacional de Desarrollo, Plan departamental de Desarrollo de Arauca, Planes municipales de desarrollo y PECTIA | N36: Modelización agroforestal, agricultura de precisión, geoeléctrica, geomicrobiología, metabolómica, análisis sensorial, evaluación molecular y validación participativa de tecnologías poscosecha | O36: Temperatura, pH, metabolitos precursores del flavour, metabolitos responsables del flavour, compuestos orgánicos volátiles, atributos sensoriales | P36: I+D+i | Q36: Equipos poscosecha, protocolos de fermentación para obtención de cacao de calidad superior | R36: Planta de bioeconomía en cacao, equipos de valorización poscosecha: Fermentador rotatorio, fermentador tipo biorreactor con control de variables de proceso, secador de alta eficiencia energética, secador por ventana refractiva, publicaciones científicas | S36: Llano, S., Zorro, A., Santander, M., Vaillant, F., Boulanger, R., Ocampo, D. M., & Escobar, S. (2025). Metabolomic insights into flavour precursor dynamics during fermentation of cacao beans cultivated in diverse climatic production zones in colombia. Food Research International, 115978. https://doi.org/10.1016/j.foodres.2025.115978 Gonzalez-Orozco, C., Porcel, M., Escobar, S., Bravo, D., Gutierrez Lopez, Y., Yockteng, R., Vaillant, F., Santander, M., Llano, S., Parra, K., Briceño, E., Carmona, J., Torres, S., Contreras, R., Otero, A., Pesca, A., & Carrillo, G. (2023). Cacao (Theobroma cacao L.) climate zones and its associated agrobiodiversity in Arauca, Colombia. Biodiversity Data Journal, 11. https://doi.org/10.3897/BDJ.11.e112771 Llano, S., Vaillant, F., Santander, M., Zorro-González, A., González-Orozco, C. E., Maraval, I., Boulanger, R., & Escobar, S. (2024). Exploring the Impact of Fermentation Time and Climate on Quality of Cocoa Bean-Derived Chocolate: Sensorial Profile and Volatilome Analysis. Foods, 13(16). https://doi.org/10.3390/foods13162614 Quintero, I., Ceccaldi, A., Martínez, H., Santander, M., Rodríguez, J., & Escobar, S. Dry cacao pulp in chocolate bars: a sustainable, nutrient-rich sweetener with enhanced sensory quality through refractance windows drying. (2025). Applied Food Research, 5(1). https://doi.org/10.1016/j.afres.2025.100700 Santander, M., Chica, V., Correa, H. A. M., Rodríguez, J., Villagran, E., Vaillant, F., & Escobar, S. (2025). Unravelling cocoa drying technology: a comprehensive review of the influence on flavor formation and quality. Foods, 14(5), 721. https://doi.org/10.3390/foods14050721 Santander, M., Leguizamón, L., Vaillant, F., Boulanger, R., Zuluaga, M., Maraval, I., Rodríguez, J., Llano, S., Sommerer, N., Meter, A., Escobar, S., & Meudec, E. (2025). Influence of driven fermentation of cacao in bioreactors on quality: decoding the effect of temperature, mixing, and ph on metabolomic, sensory, and volatile profiles. LWT-Food Science and Technology, 231, 1–12. https://doi.org/doi.org/10.1016/j.lwt.2025.118313 Zuluaga, M., Santander, M., Escobar, S., Vaillant, F. (2025). Metabolomics and peptidomics in cocoa: scientometrics analysis and systematic review of flavor-related chemical compounds in postharvest transformation. Journal of Scientometric Research; 14(3):716-731. https://jscires.org/10.5530/jscires.20251393 | T36: 1. Cajón compartimentado de madera para fermentación de cacao 2. Fermentador giratorio para tranformación poscosecha de cacao 3. Secador de alta eficiencia energética 4. Pirolizador | U36: Equipos y protocolos | V36: 3 | W36: 7 | X36: 7 | Y36: Mejora de calidad e inocuidad mediante tecnologías poscosecha estandarizadas | Z36: Incremento potencial de ingresos por acceso a mercados de cacao especial con primas superiores a US$1.000 por tonelada. | AA36: Beneficio directo a asociaciones cacaoteras de Arauca mediante fortalecimiento empresarial, transferencia tecnológica y formación de capital humano rural. | AB36: Impacto positivo al medio ambiente por uso de energías renovables (solar) en los equipos de varlozación poscosecha | AC36: Arauca | AD36: Arauquita, Saravena, Tame y Fortúl | AE36: Asociaciones de cacaocultores | AF36: 480 productores y/o asistentes técnicos | AG36: 3.500 beneficiarios: productores, comercializadores, transformadores y actores regionales de la cadena de cacao en Arauca. | AH36: Zonas cacaoteras en Colombia | AI36: Planta de Bioeconomía en cacao, Equipos de valorización poscosecha: Fermentador rotatorio, fermentador tipo biorreactor con control de variables de proceso, secador de alta eficiencia energética, secador por ventana refractiva | AK36: Entes Nacionales y Territoriales | AL36: 22.000.000 | AM36: 2019 | AN36: 2026 | AO36: En ejecución | AQ36: Calidad sensorial de cacao Protocolos de fermentación y secado Evaluación sensorial y química Escalamiento de tecnologías en cacao Diseño de equipos de poscosecha | AR36: Desarrollo de oferta tecnológica transferible Modelos territoriales replicables Capacidad de convertir ciencia en productos de valor
A37: ACI: Adaptación y resiliencia de los sistemas productivos agropecuarios frente a condiciones de clima cambiante | B37: Chontaduro | C37: Manejo ambiental y sostenibilidad | D37: Reducción del riesgo y adaptación al cambio climático_Modelos de adaptación agroclimática (MAPA). Chontaduro (Bactris gasipae) | AK37: Entes Nacionales y Territoriales
A38: Bioeconomía: Prácticas de agricultura sostenible | B38: Chontaduro | C38: Transf. de tecnologia, asist. técnica e innovación | D38: Gestión del conocimiento para el fortalecimiento productivo de los frutales del Valle del Cauca: Programa integral de Fruticultura PIF. FASE 2 | AK38: Entes Nacionales y Territoriales
A39: Bioeconomía: Prácticas de agricultura sostenible | B39: Chontaduro | C39: Material de siembra y mejoramiento genético | D39: Programa de fortalecimiento al sistema nacional de semillas producto de la intervención de sistemas locales de semillas: PLAN NACIONAL DE SEMILLAS | AK39: Entes Nacionales y Territoriales
A40: Bioeconomía: Prácticas de agricultura sostenible | B40: Chontaduro | C40: Manejo de sistemas productivos | D40: Desarrollo de estrategias para la recuperación de los sistemas productivos de Chontaduro (Bactris gasipaes) en sistemas agroforestales en zona rural del distrito de Buenaventura | AK40: Entes Nacionales y Territoriales
...

Sheet Diccionario_Capacidades
A1: Área temática | B1: Categoría | C1: Capacidad
A2: Enfermedades | B2: Emergente | C2: Monitoreo fitosanitario con herramientas digitales
A3: Enfermedades | B3: Emergente | C3: Agricultura con enfoque agroecológico
A4: Enfermedades | B4: Emergente | C4: Estudios de salud del suelo (microbioma)
A5: Enfermedades | B5: Emergente | C5: Evaluación de impacto ambiental de PQUAs
A6: Enfermedades | B6: Emergente | C6: Implementación de esquemas de aseguramiento fitosanitario (EAS)
A7: Enfermedades | B7: Emergente | C7: Estudios de resistencia genética a patógenos
A8: Enfermedades | B8: Consolidada | C8: Diagnóstico y caracterización de patógenos
A9: Enfermedades | B9: Consolidada | C9: Indexación de enfermedades
A10: Enfermedades | B10: Consolidada | C10: Limpieza fitosanitaria de material vegetal
A11: Enfermedades | B11: Consolidada | C11: Implementación de MIE en múltiples cultivos
A12: Enfermedades | B12: Consolidada | C12: Evaluación de resistencia de plantas
... A84: Poscosecha | B84: Distintiva | C84: Capacidad de convertir ciencia en productos de valor

Sheet Capacidades_CI
A1: ID capacidad | B1: Capacidad | C1: Categoría | D1: Área temática | E1: Sistema productivo | F1: Proyecto asociado | G1: Programa estratégico | H1: Investigador líder
A2: =IFERROR(IF(Portafolio_Proyectos!$AP2="","","CAP-"&ROW()-1),"") -> CAP-1 | B2: =IFERROR(IF(Portafolio_Proyectos!$AP2="","",Portafolio_Proyectos!$AP2),"") -> Indicadores de sostenibilidad ambiental | C2: =IFERROR(IF(Portafolio_Proyectos!$AP2="","","Emergente"),"") -> Emergente | D2: =IFERROR(IF(Portafolio_Proyectos!$AP2="","",Portafolio_Proyectos!$C2),"") -> Fisiología vegetal y nutrición | E2: =IFERROR(IF(Portafolio_Proyectos!$AP2="","",Portafolio_Proyectos!$B2),"") -> Aguacate Hass | F2: =IFERROR(IF(Portafolio_Proyectos!$AP2="","",Portafolio_Proyectos!$D2),"") -> Convenio 1790. Manejo integrado del cultivo | G2: =IFERROR(IF(Portafolio_Proyectos!$AP2="","",Portafolio_Proyectos!$A2),"") -> Bioeconomía: Prácticas de agricultura sostenible | H2: =IFERROR(IF(Portafolio_Proyectos!$AP2="","",Portafolio_Proyectos!$E2),"") -> Alexander Rebolledo Roa
A3: =IFERROR(IF(Portafolio_Proyectos!$AQ2="","","CAP-"&ROW()-1),"") | B3: =IFERROR(IF(Portafolio_Proyectos!$AQ2="","",Portafolio_Proyectos!$AQ2),"") | C3: =IFERROR(IF(Portafolio_Proyectos!$AQ2="","","Consolidada"),"") | D3: =IFERROR(IF(Portafolio_Proyectos!$AQ2="","",Portafolio_Proyectos!$C2),"") | E3: =IFERROR(IF(Portafolio_Proyectos!$AQ2="","",Portafolio_Proyectos!$B2),"") | F3: =IFERROR(IF(Portafolio_Proyectos!$AQ2="","",Portafolio_Proyectos!$D2),"") | G3: =IFERROR(IF(Portafolio_Proyectos!$AQ2="","",Portafolio_Proyectos!$A2),"") | H3: =IFERROR(IF(Portafolio_Proyectos!$AQ2="","",Portafolio_Proyectos!$E2),"")
A4: =IFERROR(IF(Portafolio_Proyectos!$AR2="","","CAP-"&ROW()-1),"") | B4: =IFERROR(IF(Portafolio_Proyectos!$AR2="","",Portafolio_Proyectos!$AR2),"") | C4: =IFERROR(IF(Portafolio_Proyectos!$AR2="","","Distintiva"),"") | D4: =IFERROR(IF(Portafolio_Proyectos!$AR2="","",Portafolio_Proyectos!$C2),"") | E4: =IFERROR(IF(Portafolio_Proyectos!$AR2="","",Portafolio_Proyectos!$B2),"") | F4: =IFERROR(IF(Portafolio_Proyectos!$AR2="","",Portafolio_Proyectos!$D2),"") | G4: =IFERROR(IF(Portafolio_Proyectos!$AR2="","",Portafolio_Proyectos!$A2),"") | H4: =IFERROR(IF(Portafolio_Proyectos!$AR2="","",Portafolio_Proyectos!$E2),"")
A5: =IFERROR(IF(Portafolio_Proyectos!$AP3="","","CAP-"&ROW()-1),"") | B5: =IFERROR(IF(Portafolio_Proyectos!$AP3="","",Portafolio_Proyectos!$AP3),"") | C5: =IFERROR(IF(Portafolio_Proyectos!$AP3="","","Emergente"),"") | D5: =IFERROR(IF(Portafolio_Proyectos!$AP3="","",Portafolio_Proyectos!$C3),"") | E5: =IFERROR(IF(Portafolio_Proyectos!$AP3="","",Portafolio_Proyectos!$B3),"") | F5: =IFERROR(IF(Portafolio_Proyectos!$AP3="","",Portafolio_Proyectos!$D3),"") | G5: =IFERROR(IF(Portafolio_Proyectos!$AP3="","",Portafolio_Proyectos!$A3),"") | H5: =IFERROR(IF(Portafolio_Proyectos!$AP3="","",Portafolio_Proyectos!$E3),"")
A6: =IFERROR(IF(Portafolio_Proyectos!$AQ3="","","CAP-"&ROW()-1),"") | B6: =IFERROR(IF(Portafolio_Proyectos!$AQ3="","",Portafolio_Proyectos!$AQ3),"") | C6: =IFERROR(IF(Portafolio_Proyectos!$AQ3="","","Consolidada"),"") | D6: =IFERROR(IF(Portafolio_Proyectos!$AQ3="","",Portafolio_Proyectos!$C3),"") | E6: =IFERROR(IF(Portafolio_Proyectos!$AQ3="","",Portafolio_Proyectos!$B3),"") | F6: =IFERROR(IF(Portafolio_Proyectos!$AQ3="","",Portafolio_Proyectos!$D3),"") | G6: =IFERROR(IF(Portafolio_Proyectos!$AQ3="","",Portafolio_Proyectos!$A3),"") | H6: =IFERROR(IF(Portafolio_Proyectos!$AQ3="","",Portafolio_Proyectos!$E3),"")
A7: =IFERROR(IF(Portafolio_Proyectos!$AR3="","","CAP-"&ROW()-1),"") | B7: =IFERROR(IF(Portafolio_Proyectos!$AR3="","",Portafolio_Proyectos!$AR3),"") | C7: =IFERROR(IF(Portafolio_Proyectos!$AR3="","","Distintiva"),"") | D7: =IFERROR(IF(Portafolio_Proyectos!$AR3="","",Portafolio_Proyectos!$C3),"") | E7: =IFERROR(IF(Portafolio_Proyectos!$AR3="","",Portafolio_Proyectos!$B3),"") | F7: =IFERROR(IF(Portafolio_Proyectos!$AR3="","",Portafolio_Proyectos!$D3),"") | G7: =IFERROR(IF(Portafolio_Proyectos!$AR3="","",Portafolio_Proyectos!$A3),"") | H7: =IFERROR(IF(Portafolio_Proyectos!$AR3="","",Portafolio_Proyectos!$E3),"")
A8: =IFERROR(IF(Portafolio_Proyectos!$AP4="","","CAP-"&ROW()-1),"") | B8: =IFERROR(IF(Portafolio_Proyectos!$AP4="","",Portafolio_Proyectos!$AP4),"") | C8: =IFERROR(IF(Portafolio_Proyectos!$AP4="","","Emergente"),"") | D8: =IFERROR(IF(Portafolio_Proyectos!$AP4="","",Portafolio_Proyectos!$C4),"") | E8: =IFERROR(IF(Portafolio_Proyectos!$AP4="","",Portafolio_Proyectos!$B4),"") | F8: =IFERROR(IF(Portafolio_Proyectos!$AP4="","",Portafolio_Proyectos!$D4),"") | G8: =IFERROR(IF(Portafolio_Proyectos!$AP4="","",Portafolio_Proyectos!$A4),"") | H8: =IFERROR(IF(Portafolio_Proyectos!$AP4="","",Portafolio_Proyectos!$E4),"")
A9: =IFERROR(IF(Portafolio_Proyectos!$AQ4="","","CAP-"&ROW()-1),"") | B9: =IFERROR(IF(Portafolio_Proyectos!$AQ4="","",Portafolio_Proyectos!$AQ4),"") | C9: =IFERROR(IF(Portafolio_Proyectos!$AQ4="","","Consolidada"),"") | D9: =IFERROR(IF(Portafolio_Proyectos!$AQ4="","",Portafolio_Proyectos!$C4),"") | E9: =IFERROR(IF(Portafolio_Proyectos!$AQ4="","",Portafolio_Proyectos!$B4),"") | F9: =IFERROR(IF(Portafolio_Proyectos!$AQ4="","",Portafolio_Proyectos!$D4),"") | G9: =IFERROR(IF(Portafolio_Proyectos!$AQ4="","",Portafolio_Proyectos!$A4),"") | H9: =IFERROR(IF(Portafolio_Proyectos!$AQ4="","",Portafolio_Proyectos!$E4),"")
A10: =IFERROR(IF(Portafolio_Proyectos!$AR4="","","CAP-"&ROW()-1),"") | B10: =IFERROR(IF(Portafolio_Proyectos!$AR4="","",Portafolio_Proyectos!$AR4),"") | C10: =IFERROR(IF(Portafolio_Proyectos!$AR4="","","Distintiva"),"") | D10: =IFERROR(IF(Portafolio_Proyectos!$AR4="","",Portafolio_Proyectos!$C4),"") | E10: =IFERROR(IF(Portafolio_Proyectos!$AR4="","",Portafolio_Proyectos!$B4),"") | F10: =IFERROR(IF(Portafolio_Proyectos!$AR4="","",Portafolio_Proyectos!$D4),"") | G10: =IFERROR(IF(Portafolio_Proyectos!$AR4="","",Portafolio_Proyectos!$A4),"") | H10: =IFERROR(IF(Portafolio_Proyectos!$AR4="","",Portafolio_Proyectos!$E4),"")
A11: =IFERROR(IF(Portafolio_Proyectos!$AP5="","","CAP-"&ROW()-1),"") | B11: =IFERROR(IF(Portafolio_Proyectos!$AP5="","",Portafolio_Proyectos!$AP5),"") | C11: =IFERROR(IF(Portafolio_Proyectos!$AP5="","","Emergente"),"") | D11: =IFERROR(IF(Portafolio_Proyectos!$AP5="","",Portafolio_Proyectos!$C5),"") | E11: =IFERROR(IF(Portafolio_Proyectos!$AP5="","",Portafolio_Proyectos!$B5),"") | F11: =IFERROR(IF(Portafolio_Proyectos!$AP5="","",Portafolio_Proyectos!$D5),"") | G11: =IFERROR(IF(Portafolio_Proyectos!$AP5="","",Portafolio_Proyectos!$A5),"") | H11: =IFERROR(IF(Portafolio_Proyectos!$AP5="","",Portafolio_Proyectos!$E5),"")
A12: =IFERROR(IF(Portafolio_Proyectos!$AQ5="","","CAP-"&ROW()-1),"") | B12: =IFERROR(IF(Portafolio_Proyectos!$AQ5="","",Portafolio_Proyectos!$AQ5),"") | C12: =IFERROR(IF(Portafolio_Proyectos!$AQ5="","","Consolidada"),"") | D12: =IFERROR(IF(Portafolio_Proyectos!$AQ5="","",Portafolio_Proyectos!$C5),"") | E12: =IFERROR(IF(Portafolio_Proyectos!$AQ5="","",Portafolio_Proyectos!$B5),"") | F12: =IFERROR(IF(Portafolio_Proyectos!$AQ5="","",Portafolio_Proyectos!$D5),"") | G12: =IFERROR(IF(Portafolio_Proyectos!$AQ5="","",Portafolio_Proyectos!$A5),"") | H12: =IFERROR(IF(Portafolio_Proyectos!$AQ5="","",Portafolio_Proyectos!$E5),"")
A13: =IFERROR(IF(Portafolio_Proyectos!$AR5="","","CAP-"&ROW()-1),"") | B13: =IFERROR(IF(Portafolio_Proyectos!$AR5="","",Portafolio_Proyectos!$AR5),"") | C13: =IFERROR(IF(Portafolio_Proyectos!$AR5="","","Distintiva"),"") | D13: =IFERROR(IF(Portafolio_Proyectos!$AR5="","",Portafolio_Proyectos!$C5),"") | E13: =IFERROR(IF(Portafolio_Proyectos!$AR5="","",Portafolio_Proyectos!$B5),"") | F13: =IFERROR(IF(Portafolio_Proyectos!$AR5="","",Portafolio_Proyectos!$D5),"") | G13: =IFERROR(IF(Portafolio_Proyectos!$AR5="","",Portafolio_Proyectos!$A5),"") | H13: =IFERROR(IF(Portafolio_Proyectos!$AR5="","",Portafolio_Proyectos!$E5),"")
A14: =IFERROR(IF(Portafolio_Proyectos!#REF!="","","CAP-"&ROW()-1),"") | B14: =IFERROR(IF(Portafolio_Proyectos!#REF!="","",Portafolio_Proyectos!#REF!),"") | C14: =IFERROR(IF(Portafolio_Proyectos!#REF!="","","Emergente"),"") | D14: =IFERROR(IF(Portafolio_Proyectos!#REF!="","",Portafolio_Proyectos!#REF!),"") | E14: =IFERROR(IF(Portafolio_Proyectos!#REF!="","",Portafolio_Proyectos!#REF!),"") | F14: =IFERROR(IF(Portafolio_Proyectos!#REF!="","",Portafolio_Proyectos!#REF!),"") | G14: =IFERROR(IF(Portafolio_Proyectos!#REF!="","",Portafolio_Proyectos!#REF!),"") | H14: =IFERROR(IF(Portafolio_Proyectos!#REF!="","",Portafolio_Proyectos!#REF!),"")
A15: =IFERROR(IF(Portafolio_Proyectos!#REF!="","","CAP-"&ROW()-1),"") | B15: =IFERROR(IF(Portafolio_Proyectos!#REF!="","",Portafolio_Proyectos!#REF!),"") | C15: =IFERROR(IF(Portafolio_Proyectos!#REF!="","","Consolidada"),"") | D15: =IFERROR(IF(Portafolio_Proyectos!#REF!="","",Portafolio_Proyectos!#REF!),"") | E15: =IFERROR(IF(Portafolio_Proyectos!#REF!="","",Portafolio_Proyectos!#REF!),"") | F15: =IFERROR(IF(Portafolio_Proyectos!#REF!="","",Portafolio_Proyectos!#REF!),"") | G15: =IFERROR(IF(Portafolio_Proyectos!#REF!="","",Portafolio_Proyectos!#REF!),"") | H15: =IFERROR(IF(Portafolio_Proyectos!#REF!="","",Portafolio_Proyectos!#REF!),"")
A16: =IFERROR(IF(Portafolio_Proyectos!#REF!="","","CAP-"&ROW()-1),"") | B16: =IFERROR(IF(Portafolio_Proyectos!#REF!="","",Portafolio_Proyectos!#REF!),"") | C16: =IFERROR(IF(Portafolio_Proyectos!#REF!="","","Distintiva"),"") | D16: =IFERROR(IF(Portafolio_Proyectos!#REF!="","",Portafolio_Proyectos!#REF!),"") | E16: =IFERROR(IF(Portafolio_Proyectos!#REF!="","",Portafolio_Proyectos!#REF!),"") | F16: =IFERROR(IF(Portafolio_Proyectos!#REF!="","",Portafolio_Proyectos!#REF!),"") | G16: =IFERROR(IF(Portafolio_Proyectos!#REF!="","",Portafolio_Proyectos!#REF!),"") | H16: =IFERROR(IF(Portafolio_Proyectos!#REF!="","",Portafolio_Proyectos!#REF!),"")
A17: =IFERROR(IF(Portafolio_Proyectos!$AP6="","","CAP-"&ROW()-1),"") -> CAP-16 | B17: =IFERROR(IF(Portafolio_Proyectos!$AP6="","",Portafolio_Proyectos!$AP6),"") -> Indicadores de sostenibilidad ambiental | C17: =IFERROR(IF(Portafolio_Proyectos!$AP6="","","Emergente"),"") -> Emergente | D17: =IFERROR(IF(Portafolio_Proyectos!$AP6="","",Portafolio_Proyectos!$C6),"") -> Fisiología vegetal y nutrición | E17: =IFERROR(IF(Portafolio_Proyectos!$AP6="","",Portafolio_Proyectos!$B6),"") -> Aguacate Hass | F17: =IFERROR(IF(Portafolio_Proyectos!$AP6="","",Portafolio_Proyectos!$D6),"") -> Convenio 1929. Desarrollo y validación de tecnologías para incrementar la productividad del cultivo | G17: =IFERROR(IF(Portafolio_Proyectos!$AP6="","",Portafolio_Proyectos!$A6),"") -> ACI:Productividad agrícola agroambientalmente eficiente e integralmente sostenible | H17: =IFERROR(IF(Portafolio_Proyectos!$AP6="","",Portafolio_Proyectos!$E6),"") -> Alexander Rebolledo Roa
A18: =IFERROR(IF(Portafolio_Proyectos!$AQ6="","","CAP-"&ROW()-1),"") -> CAP-17 | B18: =IFERROR(IF(Portafolio_Proyectos!$AQ6="","",Portafolio_Proyectos!$AQ6),"") -> Fertilización por sitio específico | C18: =IFERROR(IF(Portafolio_Proyectos!$AQ6="","","Consolidada"),"") -> Consolidada | D18: =IFERROR(IF(Portafolio_Proyectos!$AQ6="","",Portafolio_Proyectos!$C6),"") -> Fisiología vegetal y nutrición | E18: =IFERROR(IF(Portafolio_Proyectos!$AQ6="","",Portafolio_Proyectos!$B6),"") -> Aguacate Hass | F18: =IFERROR(IF(Portafolio_Proyectos!$AQ6="","",Portafolio_Proyectos!$D6),"") -> Convenio 1929. Desarrollo y validación de tecnologías para incrementar la productividad del cultivo | G18: =IFERROR(IF(Portafolio_Proyectos!$AQ6="","",Portafolio_Proyectos!$A6),"") -> ACI:Productividad agrícola agroambientalmente eficiente e integralmente sostenible | H18: =IFERROR(IF(Portafolio_Proyectos!$AQ6="","",Portafolio_Proyectos!$E6),"") -> Alexander Rebolledo Roa
A19: =IFERROR(IF(Portafolio_Proyectos!$AR6="","","CAP-"&ROW()-1),"") | B19: =IFERROR(IF(Portafolio_Proyectos!$AR6="","",Portafolio_Proyectos!$AR6),"") | C19: =IFERROR(IF(Portafolio_Proyectos!$AR6="","","Distintiva"),"") | D19: =IFERROR(IF(Portafolio_Proyectos!$AR6="","",Portafolio_Proyectos!$C6),"") | E19: =IFERROR(IF(Portafolio_Proyectos!$AR6="","",Portafolio_Proyectos!$B6),"") | F19: =IFERROR(IF(Portafolio_Proyectos!$AR6="","",Portafolio_Proyectos!$D6),"") | G19: =IFERROR(IF(Portafolio_Proyectos!$AR6="","",Portafolio_Proyectos!$A6),"") | H19: =IFERROR(IF(Portafolio_Proyectos!$AR6="","",Portafolio_Proyectos!$E6),"")
A20: =IFERROR(IF(Portafolio_Proyectos!$AP7="","","CAP-"&ROW()-1),"") -> CAP-19 | B20: =IFERROR(IF(Portafolio_Proyectos!$AP7="","",Portafolio_Proyectos!$AP7),"") -> Nutrición y riego para aguacate de consumo interno (Lorena) | C20: =IFERROR(IF(Portafolio_Proyectos!$AP7="","","Emergente"),"") -> Emergente | D20: =IFERROR(IF(Portafolio_Proyectos!$AP7="","",Portafolio_Proyectos!$C7),"") -> Fisiología vegetal y nutrición | E20: =IFERROR(IF(Portafolio_Proyectos!$AP7="","",Portafolio_Proyectos!$B7),"") -> Aguacate Hass | F20: =IFERROR(IF(Portafolio_Proyectos!$AP7="","",Portafolio_Proyectos!$D7),"") -> Portafolio. Fortalecimiento cadena de valor de aguacate. Convocatoria 42. SGR-Región Pacífico | G20: =IFERROR(IF(Portafolio_Proyectos!$AP7="","",Portafolio_Proyectos!$A7),"") -> ACI:Productividad agrícola agroambientalmente eficiente e integralmente sostenible | H20: =IFERROR(IF(Portafolio_Proyectos!$AP7="","",Portafolio_Proyectos!$E7),"") -> Alexander Rebolledo Roa
A21: =IFERROR(IF(Portafolio_Proyectos!$AQ7="","","CAP-"&ROW()-1),"") -> CAP-20 | B21: =IFERROR(IF(Portafolio_Proyectos!$AQ7="","",Portafolio_Proyectos!$AQ7),"") -> Fertilización por sitio específico (IBN) y riego por balance hídrico | C21: =IFERROR(IF(Portafolio_Proyectos!$AQ7="","","Consolidada"),"") -> Consolidada | D21: =IFERROR(IF(Portafolio_Proyectos!$AQ7="","",Portafolio_Proyectos!$C7),"") -> Fisiología vegetal y nutrición | E21: =IFERROR(IF(Portafolio_Proyectos!$AQ7="","",Portafolio_Proyectos!$B7),"") -> Aguacate Hass | F21: =IFERROR(IF(Portafolio_Proyectos!$AQ7="","",Portafolio_Proyectos!$D7),"") -> Portafolio. Fortalecimiento cadena de valor de aguacate. Convocatoria 42. SGR-Región Pacífico | G21: =IFERROR(IF(Portafolio_Proyectos!$AQ7="","",Portafolio_Proyectos!$A7),"") -> ACI:Productividad agrícola agroambientalmente eficiente e integralmente sostenible | H21: =IFERROR(IF(Portafolio_Proyectos!$AQ7="","",Portafolio_Proyectos!$E7),"") -> Alexander Rebolledo Roa
A22: =IFERROR(IF(Portafolio_Proyectos!$AR7="","","CAP-"&ROW()-1),"") | B22: =IFERROR(IF(Portafolio_Proyectos!$AR7="","",Portafolio_Proyectos!$AR7),"") | C22: =IFERROR(IF(Portafolio_Proyectos!$AR7="","","Distintiva"),"") | D22: =IFERROR(IF(Portafolio_Proyectos!$AR7="","",Portafolio_Proyectos!$C7),"") | E22: =IFERROR(IF(Portafolio_Proyectos!$AR7="","",Portafolio_Proyectos!$B7),"") | F22: =IFERROR(IF(Portafolio_Proyectos!$AR7="","",Portafolio_Proyectos!$D7),"") | G22: =IFERROR(IF(Portafolio_Proyectos!$AR7="","",Portafolio_Proyectos!$A7),"") | H22: =IFERROR(IF(Portafolio_Proyectos!$AR7="","",Portafolio_Proyectos!$E7),"")
